Workbook

Sheet GUIDELINES
A3: PLEASE COMPLETE THE TABS BEFORE YOU ENTER ANYTHING ON THE BUDGET PAGE. THIS BUGET HAS AUTO FILL COMPOMNENTS. THEY ARE LISTED BELOW. PLEASE COMPLETE EACH TAB NECESSARY FOR YOUR SUBMISSION. CELLS HIGHLIGTHED IN BRIGHT YELLOW SHOULD BE UPDATED FIRST. RENAME BUDGET FILE BEFORE SAVING!
A5: BUDGET | C5: PLEASE ENTER GRANT TYPE FROM DROPDOWN LIST. (FEDERAL OR NON-FEDERAL)
A8: SALARY TAB : | C8: PLEASE ENTER THE FOLLOWING ITEMS IN THE SALARY TAB:
C9: NAME AND ROLE
C10: FRINGE RATE
C11: % OF EFFORT
C12: ANNUAL IBS ( SALARY CAP WILL AUTO FILL AFTER YOU ENTER THE IBS)
C14: ** | D14: Salary increase each year based on inflation rate provided
C15: ** | D15: All salary information will auto-feed into budget worksheet
C16: ** | D16: If effort changesin outgoing years, please update effort on the salary worksheet
C17: ** | D17: Entering zero for salary in outlaying year will stop the salary projections
A19: EQUIPMENT TAB: | C19: Please list the equipment and cost for each item in the appropriate year. It will auto feed to the Budget Worksheet.
A22: PATIENT CARE COST | C22: Please enter patient care cost are excluded for IDC base
A24: SUPPLY TAB: | C24: Please list the items requested and there cost. There is automatic 3% increase each year. If you don’t' want to increase the amount by 3%, enter the amount requested manually each year on the budget worksheet
A29: SUB-AWARD TAB: | C29: Please complete subaward cost for each year. Enter the amount that should be included in the IDC base each year.
A32: PROJECT TAB: | C32: Please provide the cost breakdown for internal projects assoicated with this proposal by color coding the lines that belong to another school using the color associated with the school based on the colors below. (use the Styles tab in the Excel command ribon)
C34: College | F34: Public Health | I34: Nursing | L34: Yerkes

Sheet BUDGET
A2: TITLE:
A3: Principal Investigator (Last, First): | K3: Date
A4: DEPARTMENT | D4: Proposal Type | F4: Federal | K4: Time
A5: GRANT DATES | B5: FROM: | D5: THROUGH: | H5: Please enter end date
H7: Year 1 | L7: Year 2 | P7: Year 3 | T7: Year 4 | X7: Year 5
A8: NAME | B8: ROLE ON PROJECT | D8: Fringe Rate | E8: EFFORT (0.00) | F8: CM | G8: INST.BASE SALARY | H8: REQUESTED SALARY | I8: FRINGE BENEFITS | J8: YEAR 1 TOTAL | K8: INST.BASE SALARY | L8: REQUESTED SALARY | M8: FRINGE BENEFITS | N8: YEAR 2 TOTAL | O8: INST.BASE SALARY | P8: REQUESTED SALARY | Q8: FRINGE BENEFITS | R8: YEAR 3 TOTAL | S8: INST.BASE SALARY | T8: REQUESTED SALARY | U8: FRINGE BENEFITS | V8: YEAR 4 TOTAL | W8: INST.BASE SALARY | X8: REQUESTED SALARY | Y8: FRINGE BENEFITS | Z8: YEAR 5 TOTAL | AA8: TOTAL
A9: 0 | B9: Sub PI/ | D9: =SALARY!D10 -> 0 | E9: =SALARY!E10 -> 0 | F9: =E9*12 -> 0 | G9: =SALARY!H10 -> 0 | H9: =SALARY!I10 -> 0 | I9: =H9*D9 -> 0 | J9: =SUM(H9:I9) -> 0 | K9: =SALARY!L10 -> 0 | L9: =SALARY!M10 -> 0 | M9: =L9*D9 -> 0 | N9: =SUM(L9:M9) -> 0 | O9: =SALARY!P10 -> 0 | P9: =SALARY!Q10 -> 0 | Q9: =P9*D9 -> 0 | R9: =SUM(P9:Q9) -> 0 | S9: =SALARY!T10 -> 0 | T9: =SALARY!U10 -> 0 | U9: =T9*D9 -> 0 | V9: =SUM(T9:U9) -> 0 | W9: =SALARY!X10 -> 0 | X9: =SALARY!Y10 -> 0 | Y9: =X9*D9 -> 0 | Z9: =SUM(X9:Y9) -> 0 | AA9: =J9+N9+R9+V9+Z9 -> 0
A10: =SALARY!A11 -> 0 | B10: =SALARY!B11 -> 0 | D10: =SALARY!D11 -> 0 | E10: 0 | F10: =E10*12 -> 0 | G10: 0 | H10: =SALARY!I11 -> 0 | I10: =H10*D10 -> 0 | J10: =SUM(H10:I10) -> 0 | K10: =SALARY!L11 -> 0 | L10: =SALARY!M11 -> 0 | M10: =L10*D10 -> 0 | N10: =SUM(L10:M10) -> 0 | O10: =SALARY!P11 -> 0 | P10: =SALARY!Q11 -> 0 | Q10: =P10*D10 -> 0 | R10: =SUM(P10:Q10) -> 0 | S10: =SALARY!T11 -> 0 | T10: =SALARY!U11 -> 0 | U10: =T10*D10 -> 0 | V10: =SUM(T10:U10) -> 0 | W10: =SALARY!X11 -> 0 | X10: =SALARY!Y11 -> 0 | Y10: =X10*D10 -> 0 | Z10: =SUM(X10:Y10) -> 0 | AA10: =J10+N10+R10+V10+Z10 -> 0
A11: =SALARY!A12 -> 0 | B11: =SALARY!B12 -> 0 | D11: =SALARY!D12 -> 0 | E11: =SALARY!E12 -> 0 | F11: =ROUND(E11*12*0.92,2) -> 0 | G11: =SALARY!H12 -> 0 | H11: =SALARY!I12 -> 0 | I11: =H11*D11 -> 0 | J11: =SUM(H11:I11) -> 0 | K11: =SALARY!L12 -> 0 | L11: =SALARY!M12 -> 0 | M11: =L11*D11 -> 0 | N11: =SUM(L11:M11) -> 0 | O11: =SALARY!P12 -> 0 | P11: =SALARY!Q12 -> 0 | Q11: =P11*D11 -> 0 | R11: =SUM(P11:Q11) -> 0 | S11: =SALARY!T12 -> 0 | T11: =SALARY!U12 -> 0 | U11: =T11*D11 -> 0 | V11: =SUM(T11:U11) -> 0 | W11: =SALARY!X12 -> 0 | X11: =SALARY!Y12 -> 0 | Y11: =X11*D11 -> 0 | Z11: =SUM(X11:Y11) -> 0 | AA11: =J11+N11+R11+V11+Z11 -> 0
A12: =SALARY!A13 -> 0 | B12: =SALARY!B13 -> 0 | D12: =SALARY!D13 -> 0 | E12: =SALARY!E13 -> 0 | F12: =E12*12 -> 0 | G12: =SALARY!H13 -> 0 | H12: =SALARY!I13 -> 0 | I12: =H12*D12 -> 0 | J12: =SUM(H12:I12) -> 0 | K12: =SALARY!L13 -> 0 | L12: =SALARY!M13 -> 0 | M12: =L12*D12 -> 0 | N12: =SUM(L12:M12) -> 0 | O12: =SALARY!P13 -> 0 | P12: =SALARY!Q13 -> 0 | Q12: =P12*D12 -> 0 | R12: =SUM(P12:Q12) -> 0 | S12: =SALARY!T13 -> 0 | T12: =SALARY!U13 -> 0 | U12: =T12*D12 -> 0 | V12: =SUM(T12:U12) -> 0 | W12: =SALARY!X13 -> 0 | X12: =SALARY!Y13 -> 0 | Y12: =X12*D12 -> 0 | Z12: =SUM(X12:Y12) -> 0 | AA12: =J12+N12+R12+V12+Z12 -> 0
A13: =SALARY!A14 -> 0 | B13: =SALARY!B14 -> 0 | D13: =SALARY!D14 -> 0 | E13: =SALARY!E14 -> 0 | F13: =E13*12 -> 0 | G13: =SALARY!H14 -> 0 | H13: =SALARY!I14 -> 0 | I13: =H13*D13 -> 0 | J13: =SUM(H13:I13) -> 0 | K13: =SALARY!L14 -> 0 | L13: =SALARY!M14 -> 0 | M13: =L13*D13 -> 0 | N13: =SUM(L13:M13) -> 0 | O13: =SALARY!P14 -> 0 | P13: =SALARY!Q14 -> 0 | Q13: =P13*D13 -> 0 | R13: =SUM(P13:Q13) -> 0 | S13: =SALARY!T14 -> 0 | T13: =SALARY!U14 -> 0 | U13: =T13*D13 -> 0 | V13: =SUM(T13:U13) -> 0 | W13: =SALARY!X14 -> 0 | X13: =SALARY!Y14 -> 0 | Y13: =X13*D13 -> 0 | Z13: =SUM(X13:Y13) -> 0 | AA13: =J13+N13+R13+V13+Z13 -> 0
A14: =SALARY!A15 -> 0 | B14: =SALARY!B15 -> 0 | D14: =SALARY!D15 -> 0 | E14: =SALARY!E15 -> 0 | F14: =E14*12 -> 0 | G14: =SALARY!H15 -> 0 | H14: =SALARY!I15 -> 0 | I14: =H14*D14 -> 0 | J14: =SUM(H14:I14) -> 0 | K14: =SALARY!L15 -> 0 | L14: =SALARY!M15 -> 0 | M14: =L14*D14 -> 0 | N14: =SUM(L14:M14) -> 0 | O14: =SALARY!P15 -> 0 | P14: =SALARY!Q15 -> 0 | Q14: =P14*D14 -> 0 | R14: =SUM(P14:Q14) -> 0 | S14: =SALARY!T15 -> 0 | T14: =SALARY!U15 -> 0 | U14: =T14*D14 -> 0 | V14: =SUM(T14:U14) -> 0 | W14: =SALARY!X15 -> 0 | X14: =SALARY!Y15 -> 0 | Y14: =X14*D14 -> 0 | Z14: =SUM(X14:Y14) -> 0 | AA14: =J14+N14+R14+V14+Z14 -> 0
A15: =SALARY!A16 -> 0 | B15: =SALARY!B16 -> 0 | D15: =SALARY!D16 -> 0 | E15: =SALARY!E16 -> 0 | F15: =E15*12 -> 0 | G15: =SALARY!H16 -> 0 | H15: =SALARY!I16 -> 0 | I15: =H15*D15 -> 0 | J15: =SUM(H15:I15) -> 0 | K15: =SALARY!L16 -> 0 | L15: =SALARY!M16 -> 0 | M15: =L15*D15 -> 0 | N15: =SUM(L15:M15) -> 0 | O15: =SALARY!P16 -> 0 | P15: =SALARY!Q16 -> 0 | Q15: =P15*D15 -> 0 | R15: =SUM(P15:Q15) -> 0 | S15: =SALARY!T16 -> 0 | T15: =SALARY!U16 -> 0 | U15: =T15*D15 -> 0 | V15: =SUM(T15:U15) -> 0 | W15: =SALARY!X16 -> 0 | X15: =SALARY!Y16 -> 0 | Y15: =X15*D15 -> 0 | Z15: =SUM(X15:Y15) -> 0 | AA15: =J15+N15+R15+V15+Z15 -> 0
A16: =SALARY!A17 -> 0 | B16: =SALARY!B17 -> 0 | D16: =SALARY!D17 -> 0 | E16: =SALARY!E17 -> 0 | F16: =E16*12 -> 0 | G16: =SALARY!H17 -> 0 | H16: =SALARY!I17 -> 0 | I16: =H16*D16 -> 0 | J16: =SUM(H16:I16) -> 0 | K16: =SALARY!L17 -> 0 | L16: =SALARY!M17 -> 0 | M16: =L16*D16 -> 0 | N16: =SUM(L16:M16) -> 0 | O16: =SALARY!P17 -> 0 | P16: =SALARY!Q17 -> 0 | Q16: =P16*D16 -> 0 | R16: =SUM(P16:Q16) -> 0 | S16: =SALARY!T17 -> 0 | T16: =SALARY!U17 -> 0 | U16: =T16*D16 -> 0 | V16: =SUM(T16:U16) -> 0 | W16: =SALARY!X17 -> 0 | X16: =SALARY!Y17 -> 0 | Y16: =X16*D16 -> 0 | Z16: =SUM(X16:Y16) -> 0 | AA16: =J16+N16+R16+V16+Z16 -> 0
A17: =SALARY!A18 -> 0 | B17: =SALARY!B18 -> 0 | D17: =SALARY!D18 -> 0 | E17: =SALARY!E18 -> 0 | F17: =E17*12 -> 0 | G17: =SALARY!H18 -> 0 | H17: =SALARY!I18 -> 0 | I17: =H17*D17 -> 0 | J17: =SUM(H17:I17) -> 0 | K17: =SALARY!L18 -> 0 | L17: =SALARY!M18 -> 0 | M17: =L17*D17 -> 0 | N17: =SUM(L17:M17) -> 0 | O17: =SALARY!P18 -> 0 | P17: =SALARY!Q18 -> 0 | Q17: =P17*D17 -> 0 | R17: =SUM(P17:Q17) -> 0 | S17: =SALARY!T18 -> 0 | T17: =SALARY!U18 -> 0 | U17: =T17*D17 -> 0 | V17: =SUM(T17:U17) -> 0 | W17: =SALARY!X18 -> 0 | X17: =SALARY!Y18 -> 0 | Y17: =X17*D17 -> 0 | Z17: =SUM(X17:Y17) -> 0 | AA17: =J17+N17+R17+V17+Z17 -> 0
A18: =SALARY!A19 -> 0 | B18: =SALARY!B19 -> 0 | D18: =SALARY!D19 -> 0 | E18: =SALARY!E19 -> 0 | F18: =E18*12 -> 0 | G18: =SALARY!H19 -> 0 | H18: =SALARY!I19 -> 0 | I18: =H18*D18 -> 0 | J18: =SUM(H18:I18) -> 0 | K18: =SALARY!L19 -> 0 | L18: =SALARY!M19 -> 0 | M18: =L18*D18 -> 0 | N18: =SUM(L18:M18) -> 0 | O18: =SALARY!P19 -> 0 | P18: =SALARY!Q19 -> 0 | Q18: =P18*D18 -> 0 | R18: =SUM(P18:Q18) -> 0 | S18: =SALARY!T19 -> 0 | T18: =SALARY!U19 -> 0 | U18: =T18*D18 -> 0 | V18: =SUM(T18:U18) -> 0 | W18: =SALARY!X19 -> 0 | X18: =SALARY!Y19 -> 0 | Y18: =X18*D18 -> 0 | Z18: =SUM(X18:Y18) -> 0 | AA18: =J18+N18+R18+V18+Z18 -> 0
A19: =SALARY!A20 -> 0 | B19: =SALARY!B20 -> 0 | D19: =SALARY!D20 -> 0 | E19: =SALARY!E20 -> 0 | F19: =E19*12 -> 0 | G19: =SALARY!H20 -> 0 | H19: =SALARY!I20 -> 0 | I19: =H19*D19 -> 0 | J19: =SUM(H19:I19) -> 0 | K19: =SALARY!L20 -> 0 | L19: =SALARY!M20 -> 0 | M19: =L19*D19 -> 0 | N19: =SUM(L19:M19) -> 0 | O19: =SALARY!P20 -> 0 | P19: =SALARY!Q20 -> 0 | Q19: =P19*D19 -> 0 | R19: =SUM(P19:Q19) -> 0 | S19: =SALARY!T20 -> 0 | T19: =SALARY!U20 -> 0 | U19: =T19*D19 -> 0 | V19: =SUM(T19:U19) -> 0 | W19: =SALARY!X20 -> 0 | X19: =SALARY!Y20 -> 0 | Y19: =X19*D19 -> 0 | Z19: =SUM(X19:Y19) -> 0 | AA19: =J19+N19+R19+V19+Z19 -> 0
A20: =SALARY!A21 -> 0 | B20: =SALARY!B21 -> 0 | D20: =SALARY!D21 -> 0 | E20: =SALARY!E21 -> 0 | F20: =E20*12 -> 0 | G20: =SALARY!H21 -> 0 | H20: =SALARY!I21 -> 0 | I20: =H20*D20 -> 0 | J20: =SUM(H20:I20) -> 0 | K20: =SALARY!L21 -> 0 | L20: =SALARY!M21 -> 0 | M20: =L20*D20 -> 0 | N20: =SUM(L20:M20) -> 0 | O20: =SALARY!P21 -> 0 | P20: =SALARY!Q21 -> 0 | Q20: =P20*D20 -> 0 | R20: =SUM(P20:Q20) -> 0 | S20: =SALARY!T21 -> 0 | T20: =SALARY!U21 -> 0 | U20: =T20*D20 -> 0 | V20: =SUM(T20:U20) -> 0 | W20: =SALARY!X21 -> 0 | X20: =SALARY!Y21 -> 0 | Y20: =X20*D20 -> 0 | Z20: =SUM(X20:Y20) -> 0 | AA20: =J20+N20+R20+V20+Z20 -> 0
A21: =SALARY!A22 -> 0 | B21: =SALARY!B22 -> 0 | D21: =SALARY!D22 -> 0 | E21: =SALARY!E22 -> 0 | F21: =E21*12 -> 0 | G21: =SALARY!H22 -> 0 | H21: =SALARY!I22 -> 0 | I21: =H21*D21 -> 0 | J21: =SUM(H21:I21) -> 0 | K21: =SALARY!L22 -> 0 | L21: =SALARY!M22 -> 0 | M21: =L21*D21 -> 0 | N21: =SUM(L21:M21) -> 0 | O21: =SALARY!P22 -> 0 | P21: =SALARY!Q22 -> 0 | Q21: =P21*D21 -> 0 | R21: =SUM(P21:Q21) -> 0 | S21: =SALARY!T22 -> 0 | T21: =SALARY!U22 -> 0 | U21: =T21*D21 -> 0 | V21: =SUM(T21:U21) -> 0 | W21: =SALARY!X22 -> 0 | X21: =SALARY!Y22 -> 0 | Y21: =X21*D21 -> 0 | Z21: =SUM(X21:Y21) -> 0 | AA21: =J21+N21+R21+V21+Z21 -> 0
A22: =SALARY!A23 -> 0 | B22: =SALARY!B23 -> 0 | D22: =SALARY!D23 -> 0 | E22: =SALARY!E23 -> 0 | F22: =E22*12 -> 0 | G22: =SALARY!H23 -> 0 | H22: =SALARY!I23 -> 0 | I22: =H22*D22 -> 0 | J22: =SUM(H22:I22) -> 0 | K22: =SALARY!L23 -> 0 | L22: =SALARY!M23 -> 0 | M22: =L22*D22 -> 0 | N22: =SUM(L22:M22) -> 0 | O22: =SALARY!P23 -> 0 | P22: =SALARY!Q23 -> 0 | Q22: =P22*D22 -> 0 | R22: =SUM(P22:Q22) -> 0 | S22: =SALARY!T23 -> 0 | T22: =SALARY!U23 -> 0 | U22: =T22*D22 -> 0 | V22: =SUM(T22:U22) -> 0 | W22: =SALARY!X23 -> 0 | X22: =SALARY!Y23 -> 0 | Y22: =X22*D22 -> 0 | Z22: =SUM(X22:Y22) -> 0 | AA22: =J22+N22+R22+V22+Z22 -> 0
A23: =SALARY!A24 -> 0 | B23: =SALARY!B24 -> 0 | D23: =SALARY!D24 -> 0 | E23: =SALARY!E24 -> 0 | F23: =E23*12 -> 0 | G23: =SALARY!H24 -> 0 | H23: =SALARY!I24 -> 0 | I23: =H23*D23 -> 0 | J23: =SUM(H23:I23) -> 0 | K23: =SALARY!L24 -> 0 | L23: =SALARY!M24 -> 0 | M23: =L23*D23 -> 0 | N23: =SUM(L23:M23) -> 0 | O23: =SALARY!P24 -> 0 | P23: =SALARY!Q24 -> 0 | Q23: =P23*D23 -> 0 | R23: =SUM(P23:Q23) -> 0 | S23: =SALARY!T24 -> 0 | T23: =SALARY!U24 -> 0 | U23: =T23*D23 -> 0 | V23: =SUM(T23:U23) -> 0 | W23: =SALARY!X24 -> 0 | X23: =SALARY!Y24 -> 0 | Y23: =X23*D23 -> 0 | Z23: =SUM(X23:Y23) -> 0 | AA23: =J23+N23+R23+V23+Z23 -> 0
D24: Total Salary and Fringe Benefits | H24: =SUM(H9:H23) -> 0 | I24: =SUM(I9:I23) -> 0 | J24: =SUM(J9:J23) -> 0 | K24: =SUM(K9:K23) -> 0 | L24: =SUM(L9:L23) -> 0 | M24: =SUM(M9:M23) -> 0 | N24: =SUM(N9:N23) -> 0 | O24: =SUM(O9:O23) -> 0 | ... AA24: =SUM(AA9:AA23) -> 0
B25: DESCRIPTION | J25: AMOUNT REQUESTED | N25: AMOUNT REQUESTED | R25: AMOUNT REQUESTED | V25: AMOUNT REQUESTED | Z25: AMOUNT REQUESTED | AA25: AMOUNT REQUESTED
A26: CONSULTANT COSTS | J26: 0 | N26: 0 | R26: 0 | V26: 0 | Z26: 0 | AA26: =J26+N26+R26+V26+Z26 -> 0
A27: TUITION | B27: 0 | J27: 0 | K27: 0 | N27: 0 | O27: . | R27: 0 | S27: 0 | V27: =(R27*0.1)+R27 -> 0 | W27: 0 | Z27: =(V27*0.1)+V27 -> 0 | AA27: =J27+N27+R27+V27+Z27 -> 0
A28: EQUIPMENT | J28: ='EQUIPMENT '!B12 -> 0 | N28: ='EQUIPMENT '!C12 -> 0 | R28: ='EQUIPMENT '!D12 -> 0 | V28: ='EQUIPMENT '!E12 -> 0 | Z28: ='EQUIPMENT '!F12 -> 0 | AA28: =J28+N28+R28+V28+Z28 -> 0
A29: SUPPLIES (Please itemize on the justification) | J29: 0 | N29: 0 | R29: 0 | V29: 0 | Z29: 0 | AA29: =J29+N29+R29+V29+Z29 -> 0
A30: TRAVEL | J30: 0 | N30: 0 | R30: 0 | V30: 0 | Z30: 0 | AA30: =J30+N30+R30+V30+Z30 -> 0
A31: PATIENT CARE COSTS (Please itemize on the justification) | J31: ='PATIENT CARE'!E12 -> 0 | N31: ='PATIENT CARE'!F12 -> 0 | R31: ='PATIENT CARE'!G12 -> 0 | V31: ='PATIENT CARE'!H12 -> 0 | Z31: ='PATIENT CARE'!I12 -> 0 | AA31: =J31+N31+R31+V31+Z31 -> 0
A32: SUB-AWARD (Please itemize on "SUB-AWARD TAB") | J32: ='SUB-AWARD'!C41 -> 0 | N32: ='SUB-AWARD'!D41 -> 0 | R32: ='SUB-AWARD'!E41 -> 0 | V32: ='SUB-AWARD'!F41 -> 0 | Z32: ='SUB-AWARD'!G41 -> 0 | AA32: =J32+N32+R32+V32+Z32 -> 0
A33: OTHER EXPENSES (Please itemize on the justification) | J33: 0 | N33: 0 | R33: 0 | V33: 0 | Z33: 0 | AA33: =J33+N33+R33+V33+Z33 -> 0
A34: OTHER EXPENSES (Please itemize on the justification) | J34: 0 | N34: 0 | R34: 0 | V34: 0 | Z34: 0 | AA34: =J34+N34+R34+V34+Z34 -> 0
A35: OTHER EXPENSES (Please itemize on the justification) | J35: 0 | N35: 0 | R35: 0 | V35: 0 | Z35: 0 | AA35: =J35+N35+R35+V35+Z35 -> 0
A36: OTHER EXPENSES (Please itemize on the justification) | J36: 0 | N36: 0 | R36: 0 | V36: 0 | Z36: 0 | AA36: =J36+N36+R36+V36+Z36 -> 0
H37: Total Other Expenses | J37: =SUM(J26:J36) -> 0 | N37: =SUM(N26:N36) -> 0 | R37: =SUM(R26:R36) -> 0 | V37: =SUM(V26:V36) -> 0 | Z37: =SUM(Z26:Z36) -> 0 | AA37: =J37+N37+R37+V37+Z37 -> 0
H38: Total Expense Budget (Direct Cost) | J38: =+J24+J37 -> 0 | N38: =+N24+N37 -> 0 | R38: =+R24+R37 -> 0 | V38: =+V24+V37 -> 0 | Z38: =+Z24+Z37 -> 0 | AA38: =+AA24+AA37 -> 0
B39: Yr 1 IDC Rate | D39: Year 2 IDC Rate | G39: Indirect Cost Base | J39: =IF($F$4="Federal",(J38-J27-J28-J31-J32+'SUB-AWARD'!C42),IF($F$4="Non-Federal",J38)) -> 0 | N39: =IF($F$4="Federal",(N38-N27-N28-N31-N32+'SUB-AWARD'!D42),IF($F$4="Non-Federal",N38)) -> 0 | R39: =IF($F$4="Federal",(R38-R27-R28-R31-R32+'SUB-AWARD'!E42),IF($F$4="Non-Federal",R38)) -> 0 | V39: =IF($F$4="Federal",(V38-V27-V28-V31-V32+'SUB-AWARD'!F42),IF($F$4="Non-Federal",V38)) -> 0 | Z39: =IF($F$4="Federal",(Z38-Z27-Z28-Z31-Z32+'SUB-AWARD'!G42),IF($F$4="Non-Federal",Z38)) -> 0 | AA39: =J39+N39+R39+V39+Z39 -> 0
A40: PLEASE ENTER INDIRECT COST RATES | B40: 0.08 | D40: 0.08 | G40: Indirect cost | J40: =J39*B40 -> 0 | N40: =N39*$D$40 -> 0 | R40: =R39*$D$40 -> 0 | V40: =V39*$D$40 -> 0 | Z40: =Z39*$D$40 -> 0 | AA40: =J40+N40+R40+V40+Z40 -> 0
E41: Direct Cost without Sub Award Indirect Cost | J41: =J38-'SUB-AWARD'!C40 -> 0 | N41: =N38-'SUB-AWARD'!D40 -> 0 | R41: =R38-'SUB-AWARD'!E40 -> 0 | V41: =V38-'SUB-AWARD'!F40 -> 0 | Z41: =Z38-'SUB-AWARD'!G40 -> 0 | AA41: =J41+N41+R41+V41+Z41 -> 0
G42: TOTAL GRANT COST | J42: =J38+J40 -> 0 | N42: =N38+N40 -> 0 | R42: =R38+R40 -> 0 | V42: =V38+V40 -> 0 | Z42: =Z38+Z40 -> 0 | AA42: =AA38+AA40 -> 0
...

Sheet SALARY
A1: Fringe Rates
A2: Faculty/Staff/Post-Doc | C2: Physicians | E2: Residents | G2: Part-time | H2: Part-time
A3: Federal | C3: Federal | E3: Federal | G3: 0.0765
A4: Non-Federal | C4: Non-federal | E4: Non-Federal | G4: 0.0765
A5: Please complete yellow cells first, enter IBS, enter fringe and effort
A6: Grant Start Date | B6: 44531 | C6: Monthly Split | D6: =DATEDIF(B6,B8,"ym") -> 9 | F6: Current Year Increase | G6: =H7 -> 1 | H6: 1
A7: Current Fiscal Year | B7: 44440 | D7: =12-D6 -> 3 | F7: Annual Increase | G7: =H7 -> 1 | H7: 1
A8: Next Fiscal Year after grant start date | B8: 44805 | F8: Salary Cap | G8: =H8 -> 199300 | H8: 199300
A9: NAME | B9: ROLE ON PROJECT | D9: Fringe Rate | E9: Year 1 Effort % | F9: Current Annual IBS | G9: YR 1 Inflated Salary | H9: Year One IBS | I9: Year 1 Salary | J9: Year 2 Effort | K9: YR 2 Inflated Salary | L9: Year Two IBS | M9: Year 2 Salary | N9: Year3 Effort | O9: YR 3 Inflated Salary | P9: Year Three IBS | Q9: Year 3 Salary | R9: Year 4 Effort | S9: YR 4 Inflated Salary | T9: Year Four IBS | U9: Year 4 Salary | V9: Year 5 Effort | W9: YR 5 Inflated Salary | X9: Year Five IBS | Y9: Year 5 Salary
B10: PI | D10: =D3 -> 0 | E10: 0 | F10: 0 | G10: =(F10*$G$6/12*$D$6)+(F10*1.06/12*$D$7) -> 0 | H10: =IF(G10>=$G$8,$G$8,IF(G10<$G$8,G10)) -> 0 | I10: =H10*E10 -> 0 | J10: =E10 -> 0 | K10: =G10*$H$7 -> 0 | L10: =IF(K10>=$G$8,$G$8,IF(K10<$G$8,K10)) -> 0 | M10: =L10*J10 -> 0 | N10: =J10 -> 0 | O10: =K10*$H$7 -> 0 | P10: =IF(O10>=$G$8,$G$8,IF(O10<$G$8,O10)) -> 0 | Q10: =P10*N10 -> 0 | R10: =N10 -> 0 | S10: =O10*$H$7 -> 0 | T10: =IF(S10>=$G$8,$G$8,IF(S10<$G$8,S10)) -> 0 | U10: =T10*R10 -> 0 | V10: =R10 -> 0 | W10: =S10*$H$7 -> 0 | X10: =IF(W10>=$G$8,$G$8,IF(W10<$G$8,W10)) -> 0 | Y10: =X10*V10 -> 0
D11: =B3 -> 0 | E11: 0 | F11: 0 | G11: =(F11*$G$6/12*$D$6)+(F11*1.06/12*$D$7) -> 0 | H11: =IF(G11>=$G$8,$G$8,IF(G11<$G$8,G11)) -> 0 | I11: =H11*E11 -> 0 | J11: =E11 -> 0 | K11: =G11*$H$7 -> 0 | L11: =IF(K11>=$G$8,$G$8,IF(K11<$G$8,K11)) -> 0 | M11: =L11*J11 -> 0 | N11: =J11 -> 0 | O11: =K11*$H$7 -> 0 | P11: =IF(O11>=$G$8,$G$8,IF(O11<$G$8,O11)) -> 0 | Q11: =P11*N11 -> 0 | R11: =N11 -> 0 | S11: =O11*$H$7 -> 0 | T11: =IF(S11>=$G$8,$G$8,IF(S11<$G$8,S11)) -> 0 | U11: =T11*R11 -> 0 | V11: =R11 -> 0 | W11: =S11*$H$7 -> 0 | X11: =IF(W11>=$G$8,$G$8,IF(W11<$G$8,W11)) -> 0 | Y11: =X11*V11 -> 0
D12: =B3 -> 0 | E12: 0 | F12: 0 | G12: =(F12*$G$6/12*$D$6)+(F12*1.06/12*$D$7) -> 0 | H12: =IF(G12>=$G$8,$G$8,IF(G12<$G$8,G12)) -> 0 | I12: =H12*E12 -> 0 | J12: =E12 -> 0 | K12: =G12*$H$7 -> 0 | L12: =IF(K12>=$G$8,$G$8,IF(K12<$G$8,K12)) -> 0 | M12: =L12*J12 -> 0 | N12: =J12 -> 0 | O12: =K12*$H$7 -> 0 | P12: =IF(O12>=$G$8,$G$8,IF(O12<$G$8,O12)) -> 0 | Q12: =P12*N12 -> 0 | R12: =N12 -> 0 | S12: =O12*$H$7 -> 0 | T12: =IF(S12>=$G$8,$G$8,IF(S12<$G$8,S12)) -> 0 | U12: =T12*R12 -> 0 | V12: =R12 -> 0 | W12: =S12*$H$7 -> 0 | X12: =IF(W12>=$G$8,$G$8,IF(W12<$G$8,W12)) -> 0 | Y12: =X12*V12 -> 0
D13: =B3 -> 0 | E13: 0 | F13: 0 | G13: =(F13*$G$6/12*$D$6)+(F13*1.06/12*$D$7) -> 0 | H13: =IF(G13>=$G$8,$G$8,IF(G13<$G$8,G13)) -> 0 | I13: =H13*E13 -> 0 | J13: =E13 -> 0 | K13: =G13*$H$7 -> 0 | L13: =IF(K13>=$G$8,$G$8,IF(K13<$G$8,K13)) -> 0 | M13: =L13*J13 -> 0 | N13: =J13 -> 0 | O13: =K13*$H$7 -> 0 | P13: =IF(O13>=$G$8,$G$8,IF(O13<$G$8,O13)) -> 0 | Q13: =P13*N13 -> 0 | R13: =N13 -> 0 | S13: =O13*$H$7 -> 0 | T13: =IF(S13>=$G$8,$G$8,IF(S13<$G$8,S13)) -> 0 | U13: =T13*R13 -> 0 | V13: =R13 -> 0 | W13: =S13*$H$7 -> 0 | X13: =IF(W13>=$G$8,$G$8,IF(W13<$G$8,W13)) -> 0 | Y13: =X13*V13 -> 0
D14: =B3 -> 0 | E14: 0 | F14: 0 | G14: =(F14*$G$6/12*$D$6)+(F14*1.06/12*$D$7) -> 0 | H14: =IF(G14>=$G$8,$G$8,IF(G14<$G$8,G14)) -> 0 | I14: =H14*E14 -> 0 | J14: =E14 -> 0 | K14: =G14*$H$7 -> 0 | L14: =IF(K14>=$G$8,$G$8,IF(K14<$G$8,K14)) -> 0 | M14: =L14*J14 -> 0 | N14: =J14 -> 0 | O14: =K14*$H$7 -> 0 | P14: =IF(O14>=$G$8,$G$8,IF(O14<$G$8,O14)) -> 0 | Q14: =P14*N14 -> 0 | R14: =N14 -> 0 | S14: =O14*$H$7 -> 0 | T14: =IF(S14>=$G$8,$G$8,IF(S14<$G$8,S14)) -> 0 | U14: =T14*R14 -> 0 | V14: =R14 -> 0 | W14: =S14*$H$7 -> 0 | X14: =IF(W14>=$G$8,$G$8,IF(W14<$G$8,W14)) -> 0 | Y14: =X14*V14 -> 0
D15: 0 | E15: 0 | F15: 0 | G15: =(F15*$G$6/12*$D$6)+(F15*1.06/12*$D$7) -> 0 | H15: =IF(G15>=$G$8,$G$8,IF(G15<$G$8,G15)) -> 0 | I15: =H15*E15 -> 0 | J15: 0 | K15: =G15*$H$7 -> 0 | L15: =IF(K15>=$G$8,$G$8,IF(K15<$G$8,K15)) -> 0 | M15: =L15*J15 -> 0 | N15: 0.5 | O15: =K15*$H$7 -> 0 | P15: =IF(O15>=$G$8,$G$8,IF(O15<$G$8,O15)) -> 0 | Q15: =P15*N15 -> 0 | R15: =N15 -> 0.5 | S15: =O15*$H$7 -> 0 | T15: =IF(S15>=$G$8,$G$8,IF(S15<$G$8,S15)) -> 0 | U15: =T15*R15 -> 0 | V15: 0.5 | W15: =S15*$H$7 -> 0 | X15: =IF(W15>=$G$8,$G$8,IF(W15<$G$8,W15)) -> 0 | Y15: =X15*V15 -> 0
D16: =B3 -> 0 | E16: 0 | F16: 0 | G16: =(F16*$G$6/12*$D$6)+(F16*1.06/12*$D$7) -> 0 | H16: =IF(G16>=$G$8,$G$8,IF(G16<$G$8,G16)) -> 0 | I16: =H16*E16 -> 0 | J16: =E16 -> 0 | K16: =G16*$H$7 -> 0 | L16: =IF(K16>=$G$8,$G$8,IF(K16<$G$8,K16)) -> 0 | M16: =L16*J16 -> 0 | N16: =J16 -> 0 | O16: =K16*$H$7 -> 0 | P16: =IF(O16>=$G$8,$G$8,IF(O16<$G$8,O16)) -> 0 | Q16: =P16*N16 -> 0 | R16: =N16 -> 0 | S16: =O16*$H$7 -> 0 | T16: =IF(S16>=$G$8,$G$8,IF(S16<$G$8,S16)) -> 0 | U16: =T16*R16 -> 0 | V16: =R16 -> 0 | W16: =S16*$H$7 -> 0 | X16: =IF(W16>=$G$8,$G$8,IF(W16<$G$8,W16)) -> 0 | Y16: =X16*V16 -> 0
D17: =B3 -> 0 | E17: 0 | F17: 0 | G17: =(F17*$G$6/12*$D$6)+(F17*1.06/12*$D$7) -> 0 | H17: =IF(G17>=$G$8,$G$8,IF(G17<$G$8,G17)) -> 0 | I17: =H17*E17 -> 0 | J17: =E17 -> 0 | K17: =G17*$H$7 -> 0 | L17: =IF(K17>=$G$8,$G$8,IF(K17<$G$8,K17)) -> 0 | M17: =L17*J17 -> 0 | N17: =J17 -> 0 | O17: =K17*$H$7 -> 0 | P17: =IF(O17>=$G$8,$G$8,IF(O17<$G$8,O17)) -> 0 | Q17: =P17*N17 -> 0 | R17: =N17 -> 0 | S17: =O17*$H$7 -> 0 | T17: =IF(S17>=$G$8,$G$8,IF(S17<$G$8,S17)) -> 0 | U17: =T17*R17 -> 0 | V17: =R17 -> 0 | W17: =S17*$H$7 -> 0 | X17: =IF(W17>=$G$8,$G$8,IF(W17<$G$8,W17)) -> 0 | Y17: =X17*V17 -> 0
F18: 0 | G18: =(F18*$G$6/12*$D$6)+(F18*$G$7/12*$D$7) -> 0 | H18: =IF(G18>=$G$8,$G$8,IF(G18<$G$8,G18)) -> 0 | I18: =H18*E18 -> 0 | J18: =E18 -> 0 | K18: =G18*$H$7 -> 0 | L18: =IF(K18>=$G$8,$G$8,IF(K18<$G$8,K18)) -> 0 | M18: =L18*J18 -> 0 | N18: =J18 -> 0 | O18: =K18*$H$7 -> 0 | P18: =IF(O18>=$G$8,$G$8,IF(O18<$G$8,O18)) -> 0 | Q18: =P18*N18 -> 0 | R18: =N18 -> 0 | S18: =O18*$H$7 -> 0 | T18: =IF(S18>=$G$8,$G$8,IF(S18<$G$8,S18)) -> 0 | U18: =T18*R18 -> 0 | V18: =R18 -> 0 | W18: =S18*$H$7 -> 0 | X18: =IF(W18>=$G$8,$G$8,IF(W18<$G$8,W18)) -> 0 | Y18: =X18*V18 -> 0
F19: 0 | G19: =(F19*$G$6/12*$D$6)+(F19*$G$7/12*$D$7) -> 0 | H19: =IF(G19>=$G$8,$G$8,IF(G19<$G$8,G19)) -> 0 | I19: =H19*E19 -> 0 | J19: =E19 -> 0 | K19: =G19*$H$7 -> 0 | L19: =IF(K19>=$G$8,$G$8,IF(K19<$G$8,K19)) -> 0 | M19: =L19*J19 -> 0 | N19: =J19 -> 0 | O19: =K19*$H$7 -> 0 | P19: =IF(O19>=$G$8,$G$8,IF(O19<$G$8,O19)) -> 0 | Q19: =P19*N19 -> 0 | R19: =N19 -> 0 | S19: =O19*$H$7 -> 0 | T19: =IF(S19>=$G$8,$G$8,IF(S19<$G$8,S19)) -> 0 | U19: =T19*R19 -> 0 | V19: =R19 -> 0 | W19: =S19*$H$7 -> 0 | X19: =IF(W19>=$G$8,$G$8,IF(W19<$G$8,W19)) -> 0 | Y19: =X19*V19 -> 0
F20: 0 | G20: =(F20*$G$6/12*$D$6)+(F20*$G$7/12*$D$7) -> 0 | H20: =IF(G20>=$G$8,$G$8,IF(G20<$G$8,G20)) -> 0 | I20: =H20*E20 -> 0 | J20: =E20 -> 0 | K20: =G20*$H$7 -> 0 | L20: =IF(K20>=$G$8,$G$8,IF(K20<$G$8,K20)) -> 0 | M20: =L20*J20 -> 0 | N20: =J20 -> 0 | O20: =K20*$H$7 -> 0 | P20: =IF(O20>=$G$8,$G$8,IF(O20<$G$8,O20)) -> 0 | Q20: =P20*N20 -> 0 | R20: =N20 -> 0 | S20: =O20*$H$7 -> 0 | T20: =IF(S20>=$G$8,$G$8,IF(S20<$G$8,S20)) -> 0 | U20: =T20*R20 -> 0 | V20: =R20 -> 0 | W20: =S20*$H$7 -> 0 | X20: =IF(W20>=$G$8,$G$8,IF(W20<$G$8,W20)) -> 0 | Y20: =X20*V20 -> 0
F21: 0 | G21: =(F21*$G$6/12*$D$6)+(F21*$G$7/12*$D$7) -> 0 | H21: =IF(G21>=$G$8,$G$8,IF(G21<$G$8,G21)) -> 0 | I21: =H21*E21 -> 0 | J21: =E21 -> 0 | K21: =G21*$H$7 -> 0 | L21: =IF(K21>=$G$8,$G$8,IF(K21<$G$8,K21)) -> 0 | M21: =L21*J21 -> 0 | N21: =J21 -> 0 | O21: =K21*$H$7 -> 0 | P21: =IF(O21>=$G$8,$G$8,IF(O21<$G$8,O21)) -> 0 | Q21: =P21*N21 -> 0 | R21: =N21 -> 0 | S21: =O21*$H$7 -> 0 | T21: =IF(S21>=$G$8,$G$8,IF(S21<$G$8,S21)) -> 0 | U21: =T21*R21 -> 0 | V21: =R21 -> 0 | W21: =S21*$H$7 -> 0 | X21: =IF(W21>=$G$8,$G$8,IF(W21<$G$8,W21)) -> 0 | Y21: =X21*V21 -> 0
F22: 0 | G22: =(F22*$G$6/12*$D$6)+(F22*$G$7/12*$D$7) -> 0 | H22: =IF(G22>=$G$8,$G$8,IF(G22<$G$8,G22)) -> 0 | I22: =H22*E22 -> 0 | J22: =E22 -> 0 | K22: =G22*$H$7 -> 0 | L22: =IF(K22>=$G$8,$G$8,IF(K22<$G$8,K22)) -> 0 | M22: =L22*J22 -> 0 | N22: =J22 -> 0 | O22: =K22*$H$7 -> 0 | P22: =IF(O22>=$G$8,$G$8,IF(O22<$G$8,O22)) -> 0 | Q22: =P22*N22 -> 0 | R22: =N22 -> 0 | S22: =O22*$H$7 -> 0 | T22: =IF(S22>=$G$8,$G$8,IF(S22<$G$8,S22)) -> 0 | U22: =T22*R22 -> 0 | V22: =R22 -> 0 | W22: =S22*$H$7 -> 0 | X22: =IF(W22>=$G$8,$G$8,IF(W22<$G$8,W22)) -> 0 | Y22: =X22*V22 -> 0
F23: 0 | G23: =(F23*$G$6/12*$D$6)+(F23*$G$7/12*$D$7) -> 0 | H23: =IF(G23>=$G$8,$G$8,IF(G23<$G$8,G23)) -> 0 | I23: =H23*E23 -> 0 | J23: =E23 -> 0 | K23: =G23*$H$7 -> 0 | L23: =IF(K23>=$G$8,$G$8,IF(K23<$G$8,K23)) -> 0 | M23: =L23*J23 -> 0 | N23: =J23 -> 0 | O23: =K23*$H$7 -> 0 | P23: =IF(O23>=$G$8,$G$8,IF(O23<$G$8,O23)) -> 0 | Q23: =P23*N23 -> 0 | R23: =N23 -> 0 | S23: =O23*$H$7 -> 0 | T23: =IF(S23>=$G$8,$G$8,IF(S23<$G$8,S23)) -> 0 | U23: =T23*R23 -> 0 | V23: =R23 -> 0 | W23: =S23*$H$7 -> 0 | X23: =IF(W23>=$G$8,$G$8,IF(W23<$G$8,W23)) -> 0 | Y23: =X23*V23 -> 0
F24: 0 | G24: =(F24*$G$6/12*$D$6)+(F24*$G$7/12*$D$7) -> 0 | H24: =IF(G24>=$G$8,$G$8,IF(G24<$G$8,G24)) -> 0 | I24: =H24*E24 -> 0 | J24: =E24 -> 0 | K24: =G24*$H$7 -> 0 | L24: =IF(K24>=$G$8,$G$8,IF(K24<$G$8,K24)) -> 0 | M24: =L24*J24 -> 0 | N24: =J24 -> 0 | O24: =K24*$H$7 -> 0 | P24: =IF(O24>=$G$8,$G$8,IF(O24<$G$8,O24)) -> 0 | Q24: =P24*N24 -> 0 | R24: =N24 -> 0 | S24: =O24*$H$7 -> 0 | T24: =IF(S24>=$G$8,$G$8,IF(S24<$G$8,S24)) -> 0 | U24: =T24*R24 -> 0 | V24: =R24 -> 0 | W24: =S24*$H$7 -> 0 | X24: =IF(W24>=$G$8,$G$8,IF(W24<$G$8,W24)) -> 0 | Y24: =X24*V24 -> 0

Sheet EQUIPMENT 
A1: EQUIPMENT
A2: DESCRIPTION | B2: YR 1 COST | C2: YR 2 COST | D2: YR 3 COST | E2: YR 4 COST | F2: YR 5 COST | G2: TOTAL COST
A3: ITEM | G3: =SUM(B3:F3) -> 0
A4: ITEM | G4: =SUM(B4:F4) -> 0
A5: ITEM | G5: =SUM(B5:F5) -> 0
A6: ITEM | G6: =SUM(B6:F6) -> 0
A7: ITEM | G7: =SUM(B7:F7) -> 0
A8: ITEM | G8: =SUM(B8:F8) -> 0
A9: ITEM | G9: =SUM(B9:F9) -> 0
A10: ITEM | G10: =SUM(B10:F10) -> 0
A11: ITEM | G11: =SUM(B11:F11) -> 0
A12: TOTAL | B12: =SUM(B3:B11) -> 0 | C12: =SUM(C3:C11) -> 0 | D12: =SUM(D3:D11) -> 0 | E12: =SUM(E3:E11) -> 0 | F12: =SUM(F3:F11) -> 0 | G12: =SUM(G3:G11) -> 0

Sheet SUPPLY 
A1: SUPPLIES
A2: DESCRIPTION | B2: YR 1 COST | C2: YR 2 COST | D2: YR 3 COST | E2: YR 4 COST | F2: YR 5 COST | G2: TOTAL COST
A3: Misc | B3: 44297 | C3: 39998 | D3: 12026 | E3: 6588 | F3: 952 | G3: =SUM(B3:F3) -> 103861
A4: ITEM | C4: =B4*1.03 -> 0 | D4: =C4*1.03 -> 0 | E4: =D4*1.03 -> 0 | F4: =E4*1.03 -> 0 | G4: =SUM(B4:F4) -> 0
A5: ITEM | C5: =B5*1.03 -> 0 | D5: =C5*1.03 -> 0 | E5: =D5*1.03 -> 0 | F5: =E5*1.03 -> 0 | G5: =SUM(B5:F5) -> 0
A6: ITEM | C6: =B6*1.03 -> 0 | D6: =C6*1.03 -> 0 | E6: =D6*1.03 -> 0 | F6: =E6*1.03 -> 0 | G6: =SUM(B6:F6) -> 0
A7: ITEM | C7: =B7*1.03 -> 0 | D7: =C7*1.03 -> 0 | E7: =D7*1.03 -> 0 | F7: =E7*1.03 -> 0 | G7: =SUM(B7:F7) -> 0
A8: ITEM | C8: =B8*1.03 -> 0 | D8: =C8*1.03 -> 0 | E8: =D8*1.03 -> 0 | F8: =E8*1.03 -> 0 | G8: =SUM(B8:F8) -> 0
A9: ITEM | C9: =B9*1.03 -> 0 | D9: =C9*1.03 -> 0 | E9: =D9*1.03 -> 0 | F9: =E9*1.03 -> 0 | G9: =SUM(B9:F9) -> 0
A10: ITEM | C10: =B10*1.03 -> 0 | D10: =C10*1.03 -> 0 | E10: =D10*1.03 -> 0 | F10: =E10*1.03 -> 0 | G10: =SUM(B10:F10) -> 0
A11: ITEM | C11: =B11*1.03 -> 0 | D11: =C11*1.03 -> 0 | F11: =E11*1.03 -> 0 | G11: =SUM(B11:F11) -> 0
A12: TOTAL | B12: =SUM(B3:B11) -> 44297 | C12: =SUM(C3:C11) -> 39998 | D12: =SUM(D3:D11) -> 12026 | E12: =SUM(E3:E11) -> 6588 | F12: =SUM(F3:F11) -> 952 | G12: =SUM(G3:G11) -> 103861

Sheet PATIENT CARE
B1: PATIENT CARE COST
B2: DESCRIPTION | C2: Item Cost | D2: Number of Items Per Year | E2: YR 1 COST | F2: YR 2 COST | G2: YR 3 COST | H2: YR 4 COST | I2: YR 5 COST | J2: TOTAL COST
B3: ITEM | C3: 0 | E3: =C3*D3 -> 0 | F3: =E3*1.03 -> 0 | G3: =F3*1.03 -> 0 | H3: =G3*1.03 -> 0 | I3: =H3*1.03 -> 0 | J3: =SUM(E3:I3) -> 0
B4: ITEM | C4: 0 | E4: =C4*D4 -> 0 | F4: =E4*1.03 -> 0 | G4: =F4*1.03 -> 0 | H4: =G4*1.03 -> 0 | I4: =H4*1.03 -> 0 | J4: =SUM(E4:I4) -> 0
B5: ITEM | C5: 0 | E5: =C5*D5 -> 0 | F5: =E5*1.03 -> 0 | G5: =F5*1.03 -> 0 | H5: =G5*1.03 -> 0 | I5: =H5*1.03 -> 0 | J5: =SUM(E5:I5) -> 0
B6: ITEM | C6: 0 | E6: =C6*D6 -> 0 | F6: =E6*1.03 -> 0 | G6: =F6*1.03 -> 0 | H6: =G6*1.03 -> 0 | I6: =H6*1.03 -> 0 | J6: =SUM(E6:I6) -> 0
B7: ITEM | C7: 0 | E7: =C7*D7 -> 0 | F7: =E7*1.03 -> 0 | G7: =F7*1.03 -> 0 | H7: =G7*1.03 -> 0 | I7: =H7*1.03 -> 0 | J7: =SUM(E7:I7) -> 0
B8: ITEM | C8: 0 | E8: =C8*D8 -> 0 | F8: =E8*1.03 -> 0 | G8: =F8*1.03 -> 0 | H8: =G8*1.03 -> 0 | I8: =H8*1.03 -> 0 | J8: =SUM(E8:I8) -> 0
B9: ITEM | C9: 0 | E9: =C9*D9 -> 0 | F9: =E9*1.03 -> 0 | G9: =F9*1.03 -> 0 | H9: =G9*1.03 -> 0 | I9: =H9*1.03 -> 0 | J9: =SUM(E9:I9) -> 0
B10: ITEM | C10: 0 | E10: =C10*D10 -> 0 | F10: =E10*1.03 -> 0 | G10: =F10*1.03 -> 0 | H10: =G10*1.03 -> 0 | I10: =H10*1.03 -> 0 | J10: =SUM(E10:I10) -> 0
B11: ITEM | C11: 0 | E11: =C11*D11 -> 0 | F11: =E11*1.03 -> 0 | G11: =F11*1.03 -> 0 | I11: =H11*1.03 -> 0 | J11: =SUM(E11:I11) -> 0
B12: TOTAL | E12: =SUM(E3:E11) -> 0 | F12: =SUM(F3:F11) -> 0 | G12: =SUM(G3:G11) -> 0 | H12: =SUM(H3:H11) -> 0 | I12: =SUM(I3:I11) -> 0 | J12: =SUM(J3:J11) -> 0

Sheet SUB-AWARD
A1: SUB AWARD INFORMATION
C2: YEAR 1 | D2: YEAR 2 | E2: YEAR 3 | F2: YEAR 4 | G2: YEAR 5 | H2: TOTAL
A3: SUB AWARD 1 | B3: Name
A4: Direct Costs | H4: =SUM(C4:G4) -> 0
A5: Indirect Costs | H5: =SUM(C5:G5) -> 0
A6: TOTAL | C6: =C4+C5 -> 0 | D6: =D4+D5 -> 0 | E6: =E4+E5 -> 0 | F6: =F4+F5 -> 0 | G6: =G4+G5 -> 0 | H6: =SUM(C6:G6) -> 0
A7: Amount included in IDC Base | C7: =IF(C6<25000,C6,25000) -> 0 | D7: =IF(C7<25000,IF((C7+D6)<25000,D6,25000-C7),0) -> 0 | E7: =IF((D7+C7)<25000,IF((D7+E6+C7)<25000,E6,25000-C7-D7),0) -> 0 | F7: =IF((E7+D7+C7)<25000,IF((E7+D7+C7+F6)<25000,F6,25000-E7-D7-C7),0) -> 0 | G7: =IF((F7+E7+D7+C7)<25000,IF((C7+D7+E7+F7+G6)<25000,G6,25000-F7-E7-D7-C7),0) -> 0 | H7: =C7+D7+E7+F7+G7 -> 0
A9: SUB AWARD 2 | B9: Name
A10: Direct Costs | H10: =SUM(C10:G10) -> 0
A11: Indirect Costs | H11: =SUM(C11:G11) -> 0
A12: TOTAL | C12: =C10+C11 -> 0 | D12: =D10+D11 -> 0 | E12: =E10+E11 -> 0 | F12: =F10+F11 -> 0 | G12: =G10+G11 -> 0 | H12: =SUM(C12:G12) -> 0
A13: Amount included in IDC Base | C13: =IF(C12<25000,C12,25000) -> 0 | D13: =IF(C13<25000,IF((C13+D12)<25000,D12,25000-C13),0) -> 0 | E13: =IF((D13+C13)<25000,IF((D13+E12+C13)<25000,E12,25000-C13-D13),0) -> 0 | F13: =IF((E13+D13+C13)<25000,IF((E13+D13+C13+F12)<25000,F12,25000-E13-D13-C13),0) -> 0 | G13: =IF((F13+E13+D13+C13)<25000,IF((C13+D13+E13+F13+G12)<25000,G12,25000-F13-E13-D13-C13),0) -> 0 | H13: =C13+D13+E13+F13+G13 -> 0
A15: SUB AWARD 3 | B15: Name
A16: Direct Costs | H16: =SUM(C16:G16) -> 0
A17: Indirect Costs | H17: =SUM(C17:G17) -> 0
A18: TOTAL | C18: =C16+C17 -> 0 | D18: =D16+D17 -> 0 | E18: =E16+E17 -> 0 | F18: =F16+F17 -> 0 | G18: =G16+G17 -> 0 | H18: =SUM(C18:G18) -> 0
A19: Amount included in IDC Base | C19: =IF(C18<25000,C18,25000) -> 0 | D19: =IF(C19<25000,IF((C19+D18)<25000,D18,25000-C19),0) -> 0 | E19: =IF((D19+C19)<25000,IF((D19+E18+C19)<25000,E18,25000-C19-D19),0) -> 0 | F19: =IF((E19+D19+C19)<25000,IF((E19+D19+C19+F18)<25000,F18,25000-E19-D19-C19),0) -> 0 | G19: =IF((F19+E19+D19+C19)<25000,IF((C19+D19+E19+F19+G18)<25000,G18,25000-F19-E19-D19-C19),0) -> 0 | H19: =C19+D19+E19+F19+G19 -> 0
A21: SUB AWARD 4 | B21: Name
A22: Direct Costs | H22: =SUM(C22:G22) -> 0
A23: Indirect Costs | H23: =SUM(C23:G23) -> 0
A24: TOTAL | C24: =C22+C23 -> 0 | D24: =D22+D23 -> 0 | E24: =E22+E23 -> 0 | F24: =F22+F23 -> 0 | G24: =G22+G23 -> 0 | H24: =SUM(C24:G24) -> 0
A25: Amount included in IDC Base | C25: =IF(C24<25000,C24,25000) -> 0 | D25: =IF(C25<25000,IF((C25+D24)<25000,D24,25000-C25),0) -> 0 | E25: =IF((D25+C25)<25000,IF((D25+E24+C25)<25000,E24,25000-C25-D25),0) -> 0 | F25: =IF((E25+D25+C25)<25000,IF((E25+D25+C25+F24)<25000,F24,25000-E25-D25-C25),0) -> 0 | G25: =IF((F25+E25+D25+C25)<25000,IF((C25+D25+E25+F25+G24)<25000,G24,25000-F25-E25-D25-C25),0) -> 0 | H25: =C25+D25+E25+F25+G25 -> 0
A27: SUB AWARD 5 | B27: Name
A28: Direct Costs | H28: =SUM(C28:G28) -> 0
A29: Indirect Costs | H29: =SUM(C29:G29) -> 0
A30: TOTAL | C30: =C28+C29 -> 0 | D30: =D28+D29 -> 0 | E30: =E28+E29 -> 0 | F30: =F28+F29 -> 0 | G30: =G28+G29 -> 0 | H30: =SUM(C30:G30) -> 0
A31: Amount included in IDC Base | C31: =IF(C30<25000,C30,25000) -> 0 | D31: =IF(C31<25000,IF((C31+D30)<25000,D30,25000-C31),0) -> 0 | E31: =IF((D31+C31)<25000,IF((D31+E30+C31)<25000,E30,25000-C31-D31),0) -> 0 | F31: =IF((E31+D31+C31)<25000,IF((E31+D31+C31+F30)<25000,F30,25000-E31-D31-C31),0) -> 0 | G31: =IF((F31+E31+D31+C31)<25000,IF((C31+D31+E31+F31+G30)<25000,G30,25000-F31-E31-D31-C31),0) -> 0 | H31: =C31+D31+E31+F31+G31 -> 0
A33: SUB AWARD 6 | B33: Name
A34: Direct Costs | H34: =SUM(C34:G34) -> 0
A35: Indirect Costs | H35: =SUM(C35:G35) -> 0
A36: TOTAL | C36: =C34+C35 -> 0 | D36: =D34+D35 -> 0 | E36: =E34+E35 -> 0 | F36: =F34+F35 -> 0 | G36: =G34+G35 -> 0 | H36: =SUM(C36:G36) -> 0
A37: Amount included in IDC Base | C37: =IF(C36<25000,C36,25000) -> 0 | D37: =IF(C37<25000,IF((C37+D36)<25000,D36,25000-C37),0) -> 0 | E37: =IF((D37+C37)<25000,IF((D37+E36+C37)<25000,E36,25000-C37-D37),0) -> 0 | F37: =IF((E37+D37+C37)<25000,IF((E37+D37+C37+F36)<25000,F36,25000-E37-D37-C37),0) -> 0 | G37: =IF((F37+E37+D37+C37)<25000,IF((C37+D37+E37+F37+G36)<25000,G36,25000-F37-E37-D37-C37),0) -> 0 | H37: =C37+D37+E37+F37+G37 -> 0
A39: Total Sub-Contract Costs | C39: =C4+C10+C16+C22+C28+C34 -> 0 | D39: =D4+D10+D16+D22+D28+D34 -> 0 | E39: =E4+E10+E16+E22+E28+E34 -> 0 | F39: =F4+F10+F16+F22+F28+F34 -> 0 | G39: =G4+G10+G16+G22+G28+G34 -> 0 | H39: =H4+H10+H16+H22+H28+H34 -> 0
A40: Total Sub-Contract F&A Costs | C40: =C5+C11+C17+C23+C29+C35 -> 0 | D40: =D5+D11+D17+D23+D29+D35 -> 0 | E40: =E5+E11+E17+E23+E29+E35 -> 0 | F40: =F5+F11+F17+F23+F29+F35 -> 0 | G40: =G5+G11+G17+G23+G29+G35 -> 0 | H40: =H5+H11+H17+H23+H29+H35 -> 0
A41: TOTAL SUB AWARD | C41: =C39+C40 -> 0 | D41: =D39+D40 -> 0 | E41: =E39+E40 -> 0 | F41: =F39+F40 -> 0 | G41: =G39+G40 -> 0 | H41: =H39+H40 -> 0
A42: TOTAL IDC BASE | C42: =C7+C13+C19+C25+C31+C37 -> 0 | D42: =D7+D13+D19+D25+D31+D37 -> 0 | E42: =E7+E13+E19+E25+E31+E37 -> 0 | F42: =F7+F13+F19+F25+F31+F37 -> 0 | G42: =G7+G13+G19+G25+G31+G37 -> 0 | H42: =SUM(C42:G42) -> 0
